<?xml version="1.0" encoding="utf-8"?>
<!-- This URDF was automatically created by SolidWorks to URDF Exporter! Originally created by Stephen Brawner (brawner@gmail.com) 
     Commit Version: 1.6.0-4-g7f85cfe  Build Version: 1.6.7995.38578
     For more information, please see http://wiki.ros.org/sw_urdf_exporter -->
<robot
  name="panther_description_6">
  <link
    name="base_link">
    <inertial>
      <origin
        xyz="-5.2241152895398E-17 -4.96463192018528E-06 0.00682594884114426"
        rpy="0 0 0" />
      <mass
        value="1.00980967249859" />
      <inertia
        ixx="0.00110668630953746"
        ixy="1.22236780263816E-19"
        ixz="-3.13724589956116E-21"
        iyy="0.0011065522944672"
        iyz="-8.4529687969788E-08"
        izz="0.00216887903845609" />
    </inertial>
    <visual>
      <origin
        xyz="0 0 0"
        rpy="0 0 0" />
      <geometry>
        <mesh
          filename="package://panther_description_6/meshes/base_link.STL" />
      </geometry>
      <material
        name="">
        <color
          rgba="0.647058823529412 0.619607843137255 0.588235294117647 1" />
      </material>
    </visual>
    <collision>
      <origin
        xyz="0 0 0"
        rpy="0 0 0" />
      <geometry>
        <mesh
          filename="package://panther_description_6/meshes/base_link.STL" />
      </geometry>
    </collision>
  </link>
  <link
    name="link1">
    <inertial>
      <origin
        xyz="-0.000140138460727449 -0.0115178455380478 -0.0189175974816605"
        rpy="0 0 0" />
      <mass
        value="0.433540348958132" />
      <inertia
        ixx="0.000278935703826545"
        ixy="1.25625050632852E-06"
        ixz="6.95888805367134E-08"
        iyy="0.000266771663216221"
        iyz="6.1414956964764E-05"
        izz="0.000227700191108933" />
    </inertial>
    <visual>
      <origin
        xyz="0 0 0"
        rpy="0 0 0" />
      <geometry>
        <mesh
          filename="package://panther_description_6/meshes/link1.STL" />
      </geometry>
      <material
        name="">
        <color
          rgba="0.647058823529412 0.619607843137255 0.588235294117647 1" />
      </material>
    </visual>
    <collision>
      <origin
        xyz="0 0 0"
        rpy="0 0 0" />
      <geometry>
        <mesh
          filename="package://panther_description_6/meshes/link1.STL" />
      </geometry>
    </collision>
  </link>
  <joint
    name="joint1"
    type="revolute">
    <origin
      xyz="0 0 0.1005"
      rpy="0 0 0" />
    <parent
      link="base_link" />
    <child
      link="link1" />
    <axis
      xyz="0 0 1" />
    <limit
      lower="-3.14"
      upper="3.14"
      effort="3"
      velocity="1" />
  </joint>
  <link
    name="link2">
    <inertial>
      <origin
        xyz="0.106318068147721 -4.16333634234434E-16 0.0236482334898493"
        rpy="0 0 0" />
      <mass
        value="0.622856642139776" />
      <inertia
        ixx="0.000205489040771828"
        ixy="2.69493083500878E-19"
        ixz="-1.05315902249168E-07"
        iyy="0.00226759906569128"
        iyz="1.67836077130502E-20"
        izz="0.00241151515889848" />
    </inertial>
    <visual>
      <origin
        xyz="0 0 0"
        rpy="0 0 0" />
      <geometry>
        <mesh
          filename="package://panther_description_6/meshes/link2.STL" />
      </geometry>
      <material
        name="">
        <color
          rgba="0.827450980392157 0.827450980392157 0.819607843137255 1" />
      </material>
    </visual>
    <collision>
      <origin
        xyz="0 0 0"
        rpy="0 0 0" />
      <geometry>
        <mesh
          filename="package://panther_description_6/meshes/link2.STL" />
      </geometry>
    </collision>
  </link>
  <joint
    name="joint2"
    type="revolute">
    <origin
      xyz="0 0 0"
      rpy="1.5707963267949 0 3.14159265358979" />
    <parent
      link="link1" />
    <child
      link="link2" />
    <axis
      xyz="0 0 1" />
    <limit
      lower="-3.14"
      upper="3.14"
      effort="3"
      velocity="1" />
  </joint>
  <link
    name="link3">
    <inertial>
      <origin
        xyz="0.109732971088991 0.0113517385502648 0.0248597234802146"
        rpy="0 0 0" />
      <mass
        value="0.679340563941824" />
      <inertia
        ixx="0.000314081247177579"
        ixy="3.62847729366768E-05"
        ixz="3.17939972600301E-08"
        iyy="0.00265484041963988"
        iyz="1.00402096614936E-07"
        izz="0.00290700981572203" />
    </inertial>
    <visual>
      <origin
        xyz="0 0 0"
        rpy="0 0 0" />
      <geometry>
        <mesh
          filename="package://panther_description_6/meshes/link3.STL" />
      </geometry>
      <material
        name="">
        <color
          rgba="0.827450980392157 0.827450980392157 0.819607843137255 1" />
      </material>
    </visual>
    <collision>
      <origin
        xyz="0 0 0"
        rpy="0 0 0" />
      <geometry>
        <mesh
          filename="package://panther_description_6/meshes/link3.STL" />
      </geometry>
    </collision>
  </link>
  <joint
    name="joint3"
    type="revolute">
    <origin
      xyz="0.179999999999998 0 0"
      rpy="3.14159265358979 0 2.83491633418811" />
    <parent
      link="link2" />
    <child
      link="link3" />
    <axis
      xyz="0 0 1" />
    <limit
      lower="-3.14"
      upper="3.14"
      effort="3"
      velocity="1" />
  </joint>
  <link
    name="link4">
    <inertial>
      <origin
        xyz="0.0513406245602285 -0.032905838412701 0.00868209734629198"
        rpy="0 0 0" />
      <mass
        value="0.399529174718197" />
      <inertia
        ixx="0.000329818055330247"
        ixy="0.000104110882896881"
        ixz="8.0937605869896E-05"
        iyy="0.000360373538347201"
        iyz="-6.00949681992951E-05"
        izz="0.000376825850928195" />
    </inertial>
    <visual>
      <origin
        xyz="0 0 0"
        rpy="0 0 0" />
      <geometry>
        <mesh
          filename="package://panther_description_6/meshes/link4.STL" />
      </geometry>
      <material
        name="">
        <color
          rgba="0.827450980392157 0.827450980392157 0.819607843137255 1" />
      </material>
    </visual>
    <collision>
      <origin
        xyz="0 0 0"
        rpy="0 0 0" />
      <geometry>
        <mesh
          filename="package://panther_description_6/meshes/link4.STL" />
      </geometry>
    </collision>
  </link>
  <joint
    name="joint4"
    type="revolute">
    <origin
      xyz="0.188809427730714 0 0"
      rpy="3.14159265358979 0 -0.306676319401683" />
    <parent
      link="link3" />
    <child
      link="link4" />
    <axis
      xyz="0 0 1" />
    <limit
      lower="-3.14"
      upper="3.14"
      effort="3"
      velocity="1" />
  </joint>
  <link
    name="link5">
    <inertial>
      <origin
        xyz="0.0160776069634141 -3.55488254803203E-15 -0.0180581657290753"
        rpy="0 0 0" />
      <mass
        value="0.321861622200536" />
      <inertia
        ixx="0.000171651346378433"
        ixy="5.0956870221055E-20"
        ixz="-4.05707603604005E-05"
        iyy="0.000192352594219117"
        iyz="1.11644859685122E-19"
        izz="0.000185377128431133" />
    </inertial>
    <visual>
      <origin
        xyz="0 0 0"
        rpy="0 0 0" />
      <geometry>
        <mesh
          filename="package://panther_description_6/meshes/link5.STL" />
      </geometry>
      <material
        name="">
        <color
          rgba="0.792156862745098 0.819607843137255 0.933333333333333 1" />
      </material>
    </visual>
    <collision>
      <origin
        xyz="0 0 0"
        rpy="0 0 0" />
      <geometry>
        <mesh
          filename="package://panther_description_6/meshes/link5.STL" />
      </geometry>
    </collision>
  </link>
  <joint
    name="joint5"
    type="revolute">
    <origin
      xyz="0.0799999999999999 0 0"
      rpy="-1.5707963267949 0 0" />
    <parent
      link="link4" />
    <child
      link="link5" />
    <axis
      xyz="0 0 1" />
    <limit
      lower="-3.14"
      upper="3.14"
      effort="3"
      velocity="1" />
  </joint>
  <link
    name="link6">
    <inertial>
      <origin
        xyz="3.60105311477812E-09 -0.000284588421954529 0.0377143827584991"
        rpy="0 0 0" />
      <mass
        value="0.105249535815904" />
      <inertia
        ixx="2.77346731943087E-05"
        ixy="1.22718333526573E-16"
        ixz="1.30991468967669E-12"
        iyy="9.02469343493535E-05"
        iyz="-4.27231791224834E-07"
        izz="8.48221123206208E-05" />
    </inertial>
    <visual>
      <origin
        xyz="0 0 0"
        rpy="0 0 0" />
      <geometry>
        <mesh
          filename="package://panther_description_6/meshes/link6.STL" />
      </geometry>
      <material
        name="">
        <color
          rgba="0.827450980392157 0.827450980392157 0.819607843137255 1" />
      </material>
    </visual>
    <collision>
      <origin
        xyz="0 0 0"
        rpy="0 0 0" />
      <geometry>
        <mesh
          filename="package://panther_description_6/meshes/link6.STL" />
      </geometry>
    </collision>
  </link>
  <joint
    name="joint6"
    type="revolute">
    <origin
      xyz="0.0359999999999936 0 0"
      rpy="-1.5707963267949 0 -1.5707963267949" />
    <parent
      link="link5" />
    <child
      link="link6" />
    <axis
      xyz="0 0 1" />
    <limit
      lower="-3.14"
      upper="3.14"
      effort="3"
      velocity="1" />
  </joint>
  <link
    name="gripper_centor_link">
    <inertial>
      <origin
        xyz="3.60105311504047E-09 -0.000284588421954501 0.0377143827584991"
        rpy="0 0 0" />
      <mass
        value="0.105249535815904" />
      <inertia
        ixx="2.77346731943087E-05"
        ixy="1.22718403053125E-16"
        ixz="1.30991468977798E-12"
        iyy="9.02469343493535E-05"
        iyz="-4.27231791224835E-07"
        izz="8.48221123206208E-05" />
    </inertial>
    <visual>
      <origin
        xyz="0 0 0"
        rpy="0 0 0" />
      <geometry>
        <mesh
          filename="package://panther_description_6/meshes/gripper_centor_link.STL" />
      </geometry>
      <material
        name="">
        <color
          rgba="0.792156862745098 0.819607843137255 0.933333333333333 1" />
      </material>
    </visual>
    <collision>
      <origin
        xyz="0 0 0"
        rpy="0 0 0" />
      <geometry>
        <mesh
          filename="package://panther_description_6/meshes/gripper_centor_link.STL" />
      </geometry>
    </collision>
  </link>
  <joint
    name="gripper_centor_joint"
    type="fixed">
    <origin
      xyz="0 0 0"
      rpy="0 0 0" />
    <parent
      link="link6" />
    <child
      link="gripper_centor_link" />
    <axis
      xyz="0 0 0" />
    <limit
      lower="-3.14"
      upper="3.14"
      effort="3"
      velocity="1" />
  </joint>
  <link
    name="gripper_1_link">
    <inertial>
      <origin
        xyz="-0.0469165213249079 0.00352675466343524 0.00690853002761778"
        rpy="0 0 0" />
      <mass
        value="0.0409389598025815" />
      <inertia
        ixx="1.39994907767563E-05"
        ixy="6.6127914063864E-07"
        ixz="6.54804420464583E-07"
        iyy="1.55481122156698E-05"
        iyz="5.97877399818502E-07"
        izz="9.7441913122424E-06" />
    </inertial>
    <visual>
      <origin
        xyz="0 0 0"
        rpy="0 0 0" />
      <geometry>
        <mesh
          filename="package://panther_description_6/meshes/gripper_1_link.STL" />
      </geometry>
      <material
        name="">
        <color
          rgba="0.792156862745098 0.819607843137255 0.933333333333333 1" />
      </material>
    </visual>
    <collision>
      <origin
        xyz="0 0 0"
        rpy="0 0 0" />
      <geometry>
        <mesh
          filename="package://panther_description_6/meshes/gripper_1_link.STL" />
      </geometry>
    </collision>
  </link>
  <joint
    name="gripper_1_joint"
    type="prismatic">
    <origin
      xyz="0 0 0.138000000000007"
      rpy="3.14159265358979 -1.5707963267949 0" />
    <parent
      link="link6" />
    <child
      link="gripper_1_link" />
    <axis
      xyz="0 0 1" />
    <limit
      lower="0"
      upper="0.06"
      effort="0.18"
      velocity="1" />
  </joint>
  <link
    name="gripper_2_link">
    <inertial>
      <origin
        xyz="-0.0468917028446902 0.00381576330660352 0.00713197736004825"
        rpy="0 0 0" />
      <mass
        value="0.0410037416759648" />
      <inertia
        ixx="1.39000842886769E-05"
        ixy="6.89081844154039E-07"
        ixz="6.47795449431969E-07"
        iyy="1.53445665156082E-05"
        iyz="6.26338881883597E-07"
        izz="9.86235031142114E-06" />
    </inertial>
    <visual>
      <origin
        xyz="0 0 0"
        rpy="0 0 0" />
      <geometry>
        <mesh
          filename="package://panther_description_6/meshes/gripper_2_link.STL" />
      </geometry>
      <material
        name="">
        <color
          rgba="0.792156862745098 0.819607843137255 0.933333333333333 1" />
      </material>
    </visual>
    <collision>
      <origin
        xyz="0 0 0"
        rpy="0 0 0" />
      <geometry>
        <mesh
          filename="package://panther_description_6/meshes/gripper_2_link.STL" />
      </geometry>
    </collision>
  </link>
  <joint
    name="gripper_2_joint"
    type="prismatic">
    <origin
      xyz="0 0 0.138"
      rpy="0 -1.5708 0" />
    <parent
      link="link6" />
    <child
      link="gripper_2_link" />
    <axis
      xyz="0 0 1" />
    <limit
      lower="0"
      upper="0.06"
      effort="0.18"
      velocity="1" />
    <mimic
      joint="gripper_1_joint"
      multiplier="1"
      offset="0" />
  </joint>
</robot>