<mujoco model="Panthera_Robot">
  <compiler angle="radian"/>

  <visual>
    <global azimuth="140" elevation="-30"/>
    <headlight ambient="0.3 0.3 0.3" diffuse="0.6 0.6 0.6" specular="0 0 0"/>
    <rgba haze="0.15 0.25 0.35 1"/>
  </visual>

  <statistic extent="0.4" center="0 -0.2 0.1"/>

  <asset>
    <texture type="skybox" colorspace="auto" builtin="gradient" rgb1="0.3 0.5 0.7" rgb2="0 0 0" width="512" height="3072"/>
    <texture type="2d" colorspace="auto" name="groundplane" builtin="checker" mark="edge" rgb1="0.2 0.3 0.4" rgb2="0.1 0.2 0.3" markrgb="0.8 0.8 0.8" width="300" height="300"/>
    <texture type="2d" colorspace="linear" name="small_meta_table_diffuse" file="assets/table/small_meta_table_diffuse.png"/>
    <material name="groundplane" texture="groundplane" texuniform="true" texrepeat="5 5" reflectance="0.2"/>
    <mesh name="base_link" content_type="model/stl" file="assets/base_link.STL"/>
    <mesh name="link1" content_type="model/stl" file="assets/link1.STL"/>
    <mesh name="link2" content_type="model/stl" file="assets/link2.STL"/>
    <mesh name="link3" content_type="model/stl" file="assets/link3.STL"/>
    <mesh name="link4" content_type="model/stl" file="assets/link4.STL"/>
    <mesh name="link5" content_type="model/stl" file="assets/link5.STL"/>
    <mesh name="link6" content_type="model/stl" file="assets/link6.STL"/>
    <mesh name="gripper_centor_link" content_type="model/stl" file="assets/gripper_centor_link.STL"/>
    <mesh name="gripper_1_link" content_type="model/stl" file="assets/gripper_1_link.STL"/>
    <mesh name="gripper_2_link" content_type="model/stl" file="assets/gripper_2_link.STL"/>
  </asset>

  <worldbody>
    <geom type="mesh" rgba="0.35 0.35 0.35 1" mesh="base_link"/>
    <geom name="floor" size="0 0 0.05" type="plane" material="groundplane"/>
    <light pos="0 0 1.5" dir="0 0 -1" type="directional"/>
    <body name="link1" pos="0 0 0.1005">
      <inertial pos="-0.000140138 -0.0115178 -0.0189176" quat="0.682107 0.225427 -0.213571 0.662043" mass="0.43354" diaginertia="0.000311717 0.000278907 0.000182784"/>
      <joint name="joint1" pos="0 0 0" axis="0 0 1" range="-3.14 3.14" actuatorfrcrange="-3 3"/>
      <geom type="mesh" rgba="0.35 0.35 0.35 1" mesh="link1"/>
      <body name="link2" quat="0 0 0.707107 0.707107">
        <inertial pos="0.106425 -3.80251e-12 0.0236078" quat="0 0.70709 0 0.707124" mass="0.618785" diaginertia="0.00238697 0.002245 0.00020352"/>
        <joint name="joint2" pos="0 0 0" axis="0 0 1" range="-3.14 3.14" actuatorfrcrange="-3 3"/>
        <geom type="mesh" rgba="0.35 0.35 0.35 1" mesh="link2"/>
        <body name="link3" pos="0.18 0 0" quat="0 0.152738 0.988267 0">
          <inertial pos="0.112948 0.0109257 0.0234931" quat="0.00528254 0.707095 -0.00493839 0.707082" mass="0.578438" diaginertia="0.00237483 0.00216767 0.000267661"/>
          <joint name="joint3" pos="0 0 0" axis="0 0 1" range="-3.14 3.14" actuatorfrcrange="-3 3"/>
          <geom type="mesh" rgba="0.35 0.35 0.35 1" mesh="link3"/>
          <body name="link4" pos="0.188809 0 0" quat="0 0.988267 -0.152738 0">
            <inertial pos="0.0513406 -0.0329058 0.0086821" quat="0.43056 0.820934 0.244816 0.284165" mass="0.399529" diaginertia="0.000452305 0.00042805 0.000186662"/>
            <joint name="joint4" pos="0 0 0" axis="0 0 1" range="-3.14 3.14" actuatorfrcrange="-3 3"/>
            <geom type="mesh" rgba="0.35 0.35 0.35 1" mesh="link4"/>
            <body name="link5" pos="0.08 0 0" quat="0.499998 -0.5 0.5 0.500002">
              <inertial pos="0 -0.0160776 -0.0180582" quat="0.641375 0.297721 -0.297721 0.641375" mass="0.321862" diaginertia="0.000219661 0.000192353 0.000137367"/>
              <joint name="joint5" pos="0 0 0" axis="0 0 1" range="-3.14 3.14" actuatorfrcrange="-3 3"/>
              <geom type="mesh" rgba="0.35 0.35 0.35 1" mesh="link5"/>
              <body name="link6" pos="0 -0.036 0" quat="0.707105 0.707108 0 0">
                <inertial pos="-0.102863 -0.000273062 0.142036" quat="0.687305 -0.137368 -0.13619 0.700138" mass="0.109692" diaginertia="0.000273958 0.000244021 5.2382e-05"/>
                <joint name="joint6" pos="0 0 0" axis="0 0 1" range="-3.14 3.14" actuatorfrcrange="-3 3"/>
                <geom type="mesh" rgba="0.35 0.35 0.35 1" mesh="link6"/>
                <geom pos="0 0 0.148" quat="0.707105 0 -0.707108 0" type="mesh" rgba="0.9 0.9 0.9 1" mesh="gripper_centor_link"/>
                <body name="gripper_1_link" pos="0 0 0.148" quat="0.707105 0 -0.707108 0">
                  <inertial pos="-0.0574119 0.00266478 0.00735601" quat="0.879188 0.0380331 -0.0857256 0.467155" mass="0.042689" diaginertia="1.64659e-05 1.48003e-05 1.05472e-05"/>
                  <joint name="gripper_1_joint" pos="0 0 0" axis="0 0 1" type="slide" range="0 0.06" actuatorfrcrange="-0.18 0.18"/>
                  <geom type="mesh" rgba="0.9 0.9 0.9 1" mesh="gripper_1_link"/>
                </body>
                <body name="gripper_2_link" pos="0 0 0.148" quat="0.707105 0 -0.707108 0">
                  <inertial pos="-0.0573873 -0.00294326 -0.00756965" quat="0.447099 0.0886007 -0.0471377 0.888836" mass="0.0427537" diaginertia="1.63558e-05 1.4676e-05 1.06983e-05"/>
                  <joint name="gripper_2_joint" pos="0 0 0" axis="0 0 1" type="slide" range="-0.06 0" actuatorfrcrange="-0.18 0.18"/>
                  <geom type="mesh" rgba="0.9 0.9 0.9 1" mesh="gripper_2_link"/>
                </body>
              </body>
            </body>
          </body>
        </body>
      </body>
    </body>
  </worldbody>
</mujoco>
